<mujoco>
    <default>
        <geom type="capsule" size=".05" rgba=".9 .7 .1 1" mass="1"/>
        <joint type="hinge" axis="0 1 0" pos="0 0 0"/>
    </default>
    <actuator>
        <motor name="m1" gear="1" joint="hinge_1" ctrlrange="-100 100" ctrllimited="true"/>
        <motor name="m2" gear="1" joint="hinge_2" ctrlrange="-100 100" ctrllimited="true"/>
    </actuator>
    <option gravity="0 0 -10" timestep="0.001"/>
    <worldbody>
        <body pos="0 0 0">
            <geom name="floor" type="plane" size="10 10 0.1" rgba="0.8 0.8 0.8 1"/>
        </body>
        <body name="mass" pos="0 0 2.25">
            <site name="IMU" pos="0 0 0"/>
            <joint type="slide" axis="0 0 1"/>
            <geom type="box" size="0.25 0.25 0.25" rgba="1 0 0 1" mass="1"/>
            <body name="leg2" pos="0 0 -0.25">
                <joint name="hinge_1" limited="true" range="-90 90"/>
                <geom name="l2" fromto="0 0 -1 0 0 0" contype="0" mass=".1"/>
                <body name="leg1" pos="0 0 -1">
                    <geom name="l1" fromto="0 0 -1 0 0 0" mass=".1"/>
                    <site name="s" pos="0 0 -1"/>
                    <joint name="hinge_2" stiffness="20" damping="1.0" springref="70"/>
                </body>
            </body>
        </body>
    </worldbody>
    <sensor>
        <accelerometer name="accelerometer" site="IMU"/>
    </sensor>
</mujoco>